[2024-01-25T21:06:03.896+0000] {taskinstance.py:1956} INFO - Dependencies all met for dep_context=non-requeueable deps ti=<TaskInstance: cvd_automation_pipeline.enrich_nuclei_data_task manual__2024-01-25T21:06:00.754135+00:00 [queued]>
[2024-01-25T21:06:03.903+0000] {taskinstance.py:1956} INFO - Dependencies all met for dep_context=requeueable deps ti=<TaskInstance: cvd_automation_pipeline.enrich_nuclei_data_task manual__2024-01-25T21:06:00.754135+00:00 [queued]>
[2024-01-25T21:06:03.904+0000] {taskinstance.py:2170} INFO - Starting attempt 1 of 1
[2024-01-25T21:06:03.917+0000] {taskinstance.py:2191} INFO - Executing <Task(PythonOperator): enrich_nuclei_data_task> on 2024-01-25 21:06:00.754135+00:00
[2024-01-25T21:06:03.922+0000] {standard_task_runner.py:60} INFO - Started process 2738 to run task
[2024-01-25T21:06:03.924+0000] {standard_task_runner.py:87} INFO - Running: ['***', 'tasks', 'run', 'cvd_automation_pipeline', 'enrich_nuclei_data_task', 'manual__2024-01-25T21:06:00.754135+00:00', '--job-id', '24', '--raw', '--subdir', 'DAGS_FOLDER/test_pipeline_dag.py', '--cfg-path', '/tmp/tmplqx7d4f2']
[2024-01-25T21:06:03.925+0000] {standard_task_runner.py:88} INFO - Job 24: Subtask enrich_nuclei_data_task
[2024-01-25T21:06:03.960+0000] {task_command.py:423} INFO - Running <TaskInstance: cvd_automation_pipeline.enrich_nuclei_data_task manual__2024-01-25T21:06:00.754135+00:00 [running]> on host d1dec68e083c
[2024-01-25T21:06:04.017+0000] {taskinstance.py:2480} INFO - Exporting env vars: AIRFLOW_CTX_DAG_OWNER='***' AIRFLOW_CTX_DAG_ID='cvd_automation_pipeline' AIRFLOW_CTX_TASK_ID='enrich_nuclei_data_task' AIRFLOW_CTX_EXECUTION_DATE='2024-01-25T21:06:00.754135+00:00' AIRFLOW_CTX_TRY_NUMBER='1' AIRFLOW_CTX_DAG_RUN_ID='manual__2024-01-25T21:06:00.754135+00:00'
[2024-01-25T21:06:04.018+0000] {taskinstance.py:2698} ERROR - Task failed with exception
Traceback (most recent call last):
  File "/home/airflow/.local/lib/python3.8/site-packages/airflow/models/taskinstance.py", line 433, in _execute_task
    result = execute_callable(context=context, **execute_callable_kwargs)
  File "/home/airflow/.local/lib/python3.8/site-packages/airflow/operators/python.py", line 199, in execute
    return_value = self.execute_callable()
  File "/home/airflow/.local/lib/python3.8/site-packages/airflow/operators/python.py", line 216, in execute_callable
    return self.python_callable(*self.op_args, **self.op_kwargs)
  File "/opt/airflow/dags/test_pipeline_dag.py", line 112, in enrich_nuclei_data
    with open(nuclei_results_path, 'r') as file:
FileNotFoundError: [Errno 2] No such file or directory: 'data/2024-01-25-nuclei-results.json'
[2024-01-25T21:06:04.026+0000] {taskinstance.py:1138} INFO - Marking task as FAILED. dag_id=cvd_automation_pipeline, task_id=enrich_nuclei_data_task, execution_date=20240125T210600, start_date=20240125T210603, end_date=20240125T210604
[2024-01-25T21:06:04.036+0000] {standard_task_runner.py:107} ERROR - Failed to execute job 24 for task enrich_nuclei_data_task ([Errno 2] No such file or directory: 'data/2024-01-25-nuclei-results.json'; 2738)
[2024-01-25T21:06:04.056+0000] {local_task_job_runner.py:234} INFO - Task exited with return code 1
[2024-01-25T21:06:04.070+0000] {taskinstance.py:3280} INFO - 0 downstream tasks scheduled from follow-on schedule check
