[2024-01-25T21:43:52.964+0000] {taskinstance.py:1956} INFO - Dependencies all met for dep_context=non-requeueable deps ti=<TaskInstance: cvd_automation_pipeline.run_shodan_scan_task manual__2024-01-25T21:43:52.177511+00:00 [queued]>
[2024-01-25T21:43:52.973+0000] {taskinstance.py:1956} INFO - Dependencies all met for dep_context=requeueable deps ti=<TaskInstance: cvd_automation_pipeline.run_shodan_scan_task manual__2024-01-25T21:43:52.177511+00:00 [queued]>
[2024-01-25T21:43:52.973+0000] {taskinstance.py:2170} INFO - Starting attempt 1 of 1
[2024-01-25T21:43:52.987+0000] {taskinstance.py:2191} INFO - Executing <Task(PythonOperator): run_shodan_scan_task> on 2024-01-25 21:43:52.177511+00:00
[2024-01-25T21:43:52.991+0000] {standard_task_runner.py:60} INFO - Started process 4127 to run task
[2024-01-25T21:43:52.994+0000] {standard_task_runner.py:87} INFO - Running: ['***', 'tasks', 'run', 'cvd_automation_pipeline', 'run_shodan_scan_task', 'manual__2024-01-25T21:43:52.177511+00:00', '--job-id', '40', '--raw', '--subdir', 'DAGS_FOLDER/test_pipeline_dag.py', '--cfg-path', '/tmp/tmpdmgbwhd4']
[2024-01-25T21:43:52.995+0000] {standard_task_runner.py:88} INFO - Job 40: Subtask run_shodan_scan_task
[2024-01-25T21:43:53.034+0000] {task_command.py:423} INFO - Running <TaskInstance: cvd_automation_pipeline.run_shodan_scan_task manual__2024-01-25T21:43:52.177511+00:00 [running]> on host d1dec68e083c
[2024-01-25T21:43:53.095+0000] {taskinstance.py:2480} INFO - Exporting env vars: AIRFLOW_CTX_DAG_OWNER='***' AIRFLOW_CTX_DAG_ID='cvd_automation_pipeline' AIRFLOW_CTX_TASK_ID='run_shodan_scan_task' AIRFLOW_CTX_EXECUTION_DATE='2024-01-25T21:43:52.177511+00:00' AIRFLOW_CTX_TRY_NUMBER='1' AIRFLOW_CTX_DAG_RUN_ID='manual__2024-01-25T21:43:52.177511+00:00'
[2024-01-25T21:43:53.107+0000] {taskinstance.py:2698} ERROR - Task failed with exception
Traceback (most recent call last):
  File "/home/airflow/.local/lib/python3.8/site-packages/airflow/models/taskinstance.py", line 433, in _execute_task
    result = execute_callable(context=context, **execute_callable_kwargs)
  File "/home/airflow/.local/lib/python3.8/site-packages/airflow/operators/python.py", line 199, in execute
    return_value = self.execute_callable()
  File "/home/airflow/.local/lib/python3.8/site-packages/airflow/operators/python.py", line 216, in execute_callable
    return self.python_callable(*self.op_args, **self.op_kwargs)
  File "/opt/airflow/dags/test_pipeline_dag.py", line 56, in run_shodan_scan
    shodan_api_key = Variable.get("shodan_ak")
  File "/home/airflow/.local/lib/python3.8/site-packages/airflow/models/variable.py", line 143, in get
    raise KeyError(f"Variable {key} does not exist")
KeyError: 'Variable shodan_ak does not exist'
[2024-01-25T21:43:53.117+0000] {taskinstance.py:1138} INFO - Marking task as FAILED. dag_id=cvd_automation_pipeline, task_id=run_shodan_scan_task, execution_date=20240125T214352, start_date=20240125T214352, end_date=20240125T214353
[2024-01-25T21:43:53.127+0000] {standard_task_runner.py:107} ERROR - Failed to execute job 40 for task run_shodan_scan_task ('Variable shodan_ak does not exist'; 4127)
[2024-01-25T21:43:53.166+0000] {local_task_job_runner.py:234} INFO - Task exited with return code 1
[2024-01-25T21:43:53.187+0000] {taskinstance.py:3280} INFO - 0 downstream tasks scheduled from follow-on schedule check
