[2024-01-25T21:16:51.931+0000] {taskinstance.py:1956} INFO - Dependencies all met for dep_context=non-requeueable deps ti=<TaskInstance: cvd_automation_pipeline.enrich_nuclei_data_task manual__2024-01-25T21:16:48.594003+00:00 [queued]>
[2024-01-25T21:16:51.939+0000] {taskinstance.py:1956} INFO - Dependencies all met for dep_context=requeueable deps ti=<TaskInstance: cvd_automation_pipeline.enrich_nuclei_data_task manual__2024-01-25T21:16:48.594003+00:00 [queued]>
[2024-01-25T21:16:51.940+0000] {taskinstance.py:2170} INFO - Starting attempt 1 of 1
[2024-01-25T21:16:51.954+0000] {taskinstance.py:2191} INFO - Executing <Task(PythonOperator): enrich_nuclei_data_task> on 2024-01-25 21:16:48.594003+00:00
[2024-01-25T21:16:51.958+0000] {standard_task_runner.py:60} INFO - Started process 3116 to run task
[2024-01-25T21:16:51.960+0000] {standard_task_runner.py:87} INFO - Running: ['***', 'tasks', 'run', 'cvd_automation_pipeline', 'enrich_nuclei_data_task', 'manual__2024-01-25T21:16:48.594003+00:00', '--job-id', '27', '--raw', '--subdir', 'DAGS_FOLDER/test_pipeline_dag.py', '--cfg-path', '/tmp/tmp35a8pros']
[2024-01-25T21:16:51.961+0000] {standard_task_runner.py:88} INFO - Job 27: Subtask enrich_nuclei_data_task
[2024-01-25T21:16:51.996+0000] {task_command.py:423} INFO - Running <TaskInstance: cvd_automation_pipeline.enrich_nuclei_data_task manual__2024-01-25T21:16:48.594003+00:00 [running]> on host d1dec68e083c
[2024-01-25T21:16:52.053+0000] {taskinstance.py:2480} INFO - Exporting env vars: AIRFLOW_CTX_DAG_OWNER='***' AIRFLOW_CTX_DAG_ID='cvd_automation_pipeline' AIRFLOW_CTX_TASK_ID='enrich_nuclei_data_task' AIRFLOW_CTX_EXECUTION_DATE='2024-01-25T21:16:48.594003+00:00' AIRFLOW_CTX_TRY_NUMBER='1' AIRFLOW_CTX_DAG_RUN_ID='manual__2024-01-25T21:16:48.594003+00:00'
[2024-01-25T21:16:52.055+0000] {taskinstance.py:2698} ERROR - Task failed with exception
Traceback (most recent call last):
  File "/home/airflow/.local/lib/python3.8/site-packages/airflow/models/taskinstance.py", line 433, in _execute_task
    result = execute_callable(context=context, **execute_callable_kwargs)
  File "/home/airflow/.local/lib/python3.8/site-packages/airflow/operators/python.py", line 199, in execute
    return_value = self.execute_callable()
  File "/home/airflow/.local/lib/python3.8/site-packages/airflow/operators/python.py", line 216, in execute_callable
    return self.python_callable(*self.op_args, **self.op_kwargs)
  File "/opt/airflow/dags/test_pipeline_dag.py", line 118, in enrich_nuclei_data
    with open(nuclei_results_path, 'r') as file:
FileNotFoundError: [Errno 2] No such file or directory: 'data/2024-01-25-nuclei-results.json'
[2024-01-25T21:16:52.063+0000] {taskinstance.py:1138} INFO - Marking task as FAILED. dag_id=cvd_automation_pipeline, task_id=enrich_nuclei_data_task, execution_date=20240125T211648, start_date=20240125T211651, end_date=20240125T211652
[2024-01-25T21:16:52.071+0000] {standard_task_runner.py:107} ERROR - Failed to execute job 27 for task enrich_nuclei_data_task ([Errno 2] No such file or directory: 'data/2024-01-25-nuclei-results.json'; 3116)
[2024-01-25T21:16:52.093+0000] {local_task_job_runner.py:234} INFO - Task exited with return code 1
[2024-01-25T21:16:52.108+0000] {taskinstance.py:3280} INFO - 0 downstream tasks scheduled from follow-on schedule check
