[2024-01-25T21:21:24.756+0000] {taskinstance.py:1956} INFO - Dependencies all met for dep_context=non-requeueable deps ti=<TaskInstance: cvd_automation_pipeline.enrich_nuclei_data_task manual__2024-01-25T21:21:21.427675+00:00 [queued]>
[2024-01-25T21:21:24.764+0000] {taskinstance.py:1956} INFO - Dependencies all met for dep_context=requeueable deps ti=<TaskInstance: cvd_automation_pipeline.enrich_nuclei_data_task manual__2024-01-25T21:21:21.427675+00:00 [queued]>
[2024-01-25T21:21:24.765+0000] {taskinstance.py:2170} INFO - Starting attempt 1 of 1
[2024-01-25T21:21:24.777+0000] {taskinstance.py:2191} INFO - Executing <Task(PythonOperator): enrich_nuclei_data_task> on 2024-01-25 21:21:21.427675+00:00
[2024-01-25T21:21:24.781+0000] {standard_task_runner.py:60} INFO - Started process 3356 to run task
[2024-01-25T21:21:24.783+0000] {standard_task_runner.py:87} INFO - Running: ['***', 'tasks', 'run', 'cvd_automation_pipeline', 'enrich_nuclei_data_task', 'manual__2024-01-25T21:21:21.427675+00:00', '--job-id', '36', '--raw', '--subdir', 'DAGS_FOLDER/test_pipeline_dag.py', '--cfg-path', '/tmp/tmppnlubpld']
[2024-01-25T21:21:24.784+0000] {standard_task_runner.py:88} INFO - Job 36: Subtask enrich_nuclei_data_task
[2024-01-25T21:21:24.818+0000] {task_command.py:423} INFO - Running <TaskInstance: cvd_automation_pipeline.enrich_nuclei_data_task manual__2024-01-25T21:21:21.427675+00:00 [running]> on host d1dec68e083c
[2024-01-25T21:21:24.875+0000] {taskinstance.py:2480} INFO - Exporting env vars: AIRFLOW_CTX_DAG_OWNER='***' AIRFLOW_CTX_DAG_ID='cvd_automation_pipeline' AIRFLOW_CTX_TASK_ID='enrich_nuclei_data_task' AIRFLOW_CTX_EXECUTION_DATE='2024-01-25T21:21:21.427675+00:00' AIRFLOW_CTX_TRY_NUMBER='1' AIRFLOW_CTX_DAG_RUN_ID='manual__2024-01-25T21:21:21.427675+00:00'
[2024-01-25T21:21:24.876+0000] {taskinstance.py:2698} ERROR - Task failed with exception
Traceback (most recent call last):
  File "/home/airflow/.local/lib/python3.8/site-packages/airflow/models/taskinstance.py", line 433, in _execute_task
    result = execute_callable(context=context, **execute_callable_kwargs)
  File "/home/airflow/.local/lib/python3.8/site-packages/airflow/operators/python.py", line 199, in execute
    return_value = self.execute_callable()
  File "/home/airflow/.local/lib/python3.8/site-packages/airflow/operators/python.py", line 216, in execute_callable
    return self.python_callable(*self.op_args, **self.op_kwargs)
  File "/opt/airflow/dags/test_pipeline_dag.py", line 120, in enrich_nuclei_data
    with open(nuclei_results_path, 'r') as file:
FileNotFoundError: [Errno 2] No such file or directory: 'data/2024-01-25-nuclei-results.json'
[2024-01-25T21:21:24.884+0000] {taskinstance.py:1138} INFO - Marking task as FAILED. dag_id=cvd_automation_pipeline, task_id=enrich_nuclei_data_task, execution_date=20240125T212121, start_date=20240125T212124, end_date=20240125T212124
[2024-01-25T21:21:24.893+0000] {standard_task_runner.py:107} ERROR - Failed to execute job 36 for task enrich_nuclei_data_task ([Errno 2] No such file or directory: 'data/2024-01-25-nuclei-results.json'; 3356)
[2024-01-25T21:21:24.915+0000] {local_task_job_runner.py:234} INFO - Task exited with return code 1
[2024-01-25T21:21:24.929+0000] {taskinstance.py:3280} INFO - 0 downstream tasks scheduled from follow-on schedule check
