[2024-01-25T21:45:24.236+0000] {taskinstance.py:1956} INFO - Dependencies all met for dep_context=non-requeueable deps ti=<TaskInstance: cvd_automation_pipeline.enrich_nuclei_data_task manual__2024-01-25T21:44:58.217244+00:00 [queued]>
[2024-01-25T21:45:24.244+0000] {taskinstance.py:1956} INFO - Dependencies all met for dep_context=requeueable deps ti=<TaskInstance: cvd_automation_pipeline.enrich_nuclei_data_task manual__2024-01-25T21:44:58.217244+00:00 [queued]>
[2024-01-25T21:45:24.244+0000] {taskinstance.py:2170} INFO - Starting attempt 1 of 1
[2024-01-25T21:45:24.258+0000] {taskinstance.py:2191} INFO - Executing <Task(PythonOperator): enrich_nuclei_data_task> on 2024-01-25 21:44:58.217244+00:00
[2024-01-25T21:45:24.262+0000] {standard_task_runner.py:60} INFO - Started process 4222 to run task
[2024-01-25T21:45:24.264+0000] {standard_task_runner.py:87} INFO - Running: ['***', 'tasks', 'run', 'cvd_automation_pipeline', 'enrich_nuclei_data_task', 'manual__2024-01-25T21:44:58.217244+00:00', '--job-id', '43', '--raw', '--subdir', 'DAGS_FOLDER/test_pipeline_dag.py', '--cfg-path', '/tmp/tmpz_n1uv8b']
[2024-01-25T21:45:24.266+0000] {standard_task_runner.py:88} INFO - Job 43: Subtask enrich_nuclei_data_task
[2024-01-25T21:45:24.309+0000] {task_command.py:423} INFO - Running <TaskInstance: cvd_automation_pipeline.enrich_nuclei_data_task manual__2024-01-25T21:44:58.217244+00:00 [running]> on host d1dec68e083c
[2024-01-25T21:45:24.368+0000] {taskinstance.py:2480} INFO - Exporting env vars: AIRFLOW_CTX_DAG_OWNER='***' AIRFLOW_CTX_DAG_ID='cvd_automation_pipeline' AIRFLOW_CTX_TASK_ID='enrich_nuclei_data_task' AIRFLOW_CTX_EXECUTION_DATE='2024-01-25T21:44:58.217244+00:00' AIRFLOW_CTX_TRY_NUMBER='1' AIRFLOW_CTX_DAG_RUN_ID='manual__2024-01-25T21:44:58.217244+00:00'
[2024-01-25T21:45:24.371+0000] {taskinstance.py:2698} ERROR - Task failed with exception
Traceback (most recent call last):
  File "/home/airflow/.local/lib/python3.8/site-packages/airflow/models/taskinstance.py", line 433, in _execute_task
    result = execute_callable(context=context, **execute_callable_kwargs)
  File "/home/airflow/.local/lib/python3.8/site-packages/airflow/operators/python.py", line 199, in execute
    return_value = self.execute_callable()
  File "/home/airflow/.local/lib/python3.8/site-packages/airflow/operators/python.py", line 216, in execute_callable
    return self.python_callable(*self.op_args, **self.op_kwargs)
  File "/opt/airflow/dags/test_pipeline_dag.py", line 124, in enrich_nuclei_data
    nuclei_data = json.load(file)
  File "/usr/local/lib/python3.8/json/__init__.py", line 293, in load
    return loads(fp.read(),
  File "/usr/local/lib/python3.8/json/__init__.py", line 357, in loads
    return _default_decoder.decode(s)
  File "/usr/local/lib/python3.8/json/decoder.py", line 337, in decode
    obj, end = self.raw_decode(s, idx=_w(s, 0).end())
  File "/usr/local/lib/python3.8/json/decoder.py", line 355, in raw_decode
    raise JSONDecodeError("Expecting value", s, err.value) from None
json.decoder.JSONDecodeError: Expecting value: line 1 column 1 (char 0)
[2024-01-25T21:45:24.380+0000] {taskinstance.py:1138} INFO - Marking task as FAILED. dag_id=cvd_automation_pipeline, task_id=enrich_nuclei_data_task, execution_date=20240125T214458, start_date=20240125T214524, end_date=20240125T214524
[2024-01-25T21:45:24.391+0000] {standard_task_runner.py:107} ERROR - Failed to execute job 43 for task enrich_nuclei_data_task (Expecting value: line 1 column 1 (char 0); 4222)
[2024-01-25T21:45:24.397+0000] {local_task_job_runner.py:234} INFO - Task exited with return code 1
[2024-01-25T21:45:24.411+0000] {taskinstance.py:3280} INFO - 0 downstream tasks scheduled from follow-on schedule check
