[2024-01-25T23:37:01.598+0000] {taskinstance.py:1956} INFO - Dependencies all met for dep_context=non-requeueable deps ti=<TaskInstance: cvd_automation_pipeline.run_shodan_scan_task manual__2024-01-25T23:36:59.137762+00:00 [queued]>
[2024-01-25T23:37:01.635+0000] {taskinstance.py:1956} INFO - Dependencies all met for dep_context=requeueable deps ti=<TaskInstance: cvd_automation_pipeline.run_shodan_scan_task manual__2024-01-25T23:36:59.137762+00:00 [queued]>
[2024-01-25T23:37:01.636+0000] {taskinstance.py:2170} INFO - Starting attempt 1 of 1
[2024-01-25T23:37:01.699+0000] {taskinstance.py:2191} INFO - Executing <Task(PythonOperator): run_shodan_scan_task> on 2024-01-25 23:36:59.137762+00:00
[2024-01-25T23:37:01.708+0000] {standard_task_runner.py:60} INFO - Started process 264 to run task
[2024-01-25T23:37:01.717+0000] {standard_task_runner.py:87} INFO - Running: ['***', 'tasks', 'run', 'cvd_automation_pipeline', 'run_shodan_scan_task', 'manual__2024-01-25T23:36:59.137762+00:00', '--job-id', '3', '--raw', '--subdir', 'DAGS_FOLDER/cvd_pipeline_1.py', '--cfg-path', '/tmp/tmp_ufp4c3y']
[2024-01-25T23:37:01.721+0000] {standard_task_runner.py:88} INFO - Job 3: Subtask run_shodan_scan_task
[2024-01-25T23:37:01.902+0000] {task_command.py:423} INFO - Running <TaskInstance: cvd_automation_pipeline.run_shodan_scan_task manual__2024-01-25T23:36:59.137762+00:00 [running]> on host 6cac4319e35a
[2024-01-25T23:37:02.098+0000] {taskinstance.py:2480} INFO - Exporting env vars: AIRFLOW_CTX_DAG_OWNER='***' AIRFLOW_CTX_DAG_ID='cvd_automation_pipeline' AIRFLOW_CTX_TASK_ID='run_shodan_scan_task' AIRFLOW_CTX_EXECUTION_DATE='2024-01-25T23:36:59.137762+00:00' AIRFLOW_CTX_TRY_NUMBER='1' AIRFLOW_CTX_DAG_RUN_ID='manual__2024-01-25T23:36:59.137762+00:00'
[2024-01-25T23:37:02.116+0000] {taskinstance.py:2698} ERROR - Task failed with exception
Traceback (most recent call last):
  File "/home/airflow/.local/lib/python3.8/site-packages/airflow/models/taskinstance.py", line 433, in _execute_task
    result = execute_callable(context=context, **execute_callable_kwargs)
  File "/home/airflow/.local/lib/python3.8/site-packages/airflow/operators/python.py", line 199, in execute
    return_value = self.execute_callable()
  File "/home/airflow/.local/lib/python3.8/site-packages/airflow/operators/python.py", line 216, in execute_callable
    return self.python_callable(*self.op_args, **self.op_kwargs)
  File "/opt/airflow/dags/cvd_pipeline_1.py", line 55, in run_shodan_scan
    shodan_search_phrase = Variable.get("shodan_search_phrase")
  File "/home/airflow/.local/lib/python3.8/site-packages/airflow/models/variable.py", line 143, in get
    raise KeyError(f"Variable {key} does not exist")
KeyError: 'Variable shodan_search_phrase does not exist'
[2024-01-25T23:37:02.135+0000] {taskinstance.py:1138} INFO - Marking task as FAILED. dag_id=cvd_automation_pipeline, task_id=run_shodan_scan_task, execution_date=20240125T233659, start_date=20240125T233701, end_date=20240125T233702
[2024-01-25T23:37:02.164+0000] {standard_task_runner.py:107} ERROR - Failed to execute job 3 for task run_shodan_scan_task ('Variable shodan_search_phrase does not exist'; 264)
[2024-01-25T23:37:02.219+0000] {local_task_job_runner.py:234} INFO - Task exited with return code 1
[2024-01-25T23:37:02.255+0000] {taskinstance.py:3280} INFO - 0 downstream tasks scheduled from follow-on schedule check
